INFO:     Started server process [657924]
INFO:     Waiting for application startup.
2025-03-14 13:54:58,633 - app - INFO - Initializing Gazelle model...
Using cache found in /home/spectre/.cache/torch/hub/fkryan_gazelle_main
Using cache found in /home/spectre/.cache/torch/hub/facebookresearch_dinov2_main
/home/spectre/.cache/torch/hub/facebookresearch_dinov2_main/dinov2/layers/swiglu_ffn.py:51: UserWarning: xFormers is not available (SwiGLU)
  warnings.warn("xFormers is not available (SwiGLU)")
/home/spectre/.cache/torch/hub/facebookresearch_dinov2_main/dinov2/layers/attention.py:33: UserWarning: xFormers is not available (Attention)
  warnings.warn("xFormers is not available (Attention)")
/home/spectre/.cache/torch/hub/facebookresearch_dinov2_main/dinov2/layers/block.py:40: UserWarning: xFormers is not available (Block)
  warnings.warn("xFormers is not available (Block)")
2025-03-14 13:55:03,161 - dinov2 - INFO - using MLP layer as FFN
2025-03-14 13:55:10,394 - app - INFO - Model initialized on cpu
{"is_panic":false,"message":"Can't reach database server at `localhost:5432`\n\nPlease make sure your database server is running at `localhost:5432`.","meta":{"database_host":"localhost","database_port":5432},"error_code":"P1001"}
ERROR:    Traceback (most recent call last):
  File "/home/spectre/.virtualenvs/localize/lib/python3.10/site-packages/httpx/_transports/default.py", line 101, in map_httpcore_exceptions
    yield
  File "/home/spectre/.virtualenvs/localize/lib/python3.10/site-packages/httpx/_transports/default.py", line 394, in handle_async_request
    resp = await self._pool.handle_async_request(req)
  File "/home/spectre/.virtualenvs/localize/lib/python3.10/site-packages/httpcore/_async/connection_pool.py", line 256, in handle_async_request
    raise exc from None
  File "/home/spectre/.virtualenvs/localize/lib/python3.10/site-packages/httpcore/_async/connection_pool.py", line 236, in handle_async_request
    response = await connection.handle_async_request(
  File "/home/spectre/.virtualenvs/localize/lib/python3.10/site-packages/httpcore/_async/connection.py", line 101, in handle_async_request
    raise exc
  File "/home/spectre/.virtualenvs/localize/lib/python3.10/site-packages/httpcore/_async/connection.py", line 78, in handle_async_request
    stream = await self._connect(request)
  File "/home/spectre/.virtualenvs/localize/lib/python3.10/site-packages/httpcore/_async/connection.py", line 124, in _connect
    stream = await self._network_backend.connect_tcp(**kwargs)
  File "/home/spectre/.virtualenvs/localize/lib/python3.10/site-packages/httpcore/_backends/auto.py", line 31, in connect_tcp
    return await self._backend.connect_tcp(
  File "/home/spectre/.virtualenvs/localize/lib/python3.10/site-packages/httpcore/_backends/anyio.py", line 113, in connect_tcp
    with map_exceptions(exc_map):
  File "/usr/lib/python3.10/contextlib.py", line 153, in __exit__
    self.gen.throw(typ, value, traceback)
  File "/home/spectre/.virtualenvs/localize/lib/python3.10/site-packages/httpcore/_exceptions.py", line 14, in map_exceptions
    raise to_exc(exc) from exc
httpcore.ConnectError: All connection attempts failed

The above exception was the direct cause of the following exception:

Traceback (most recent call last):
  File "/home/spectre/.virtualenvs/localize/lib/python3.10/site-packages/prisma/engine/_query.py", line 368, in spawn
    data = await self.request('GET', '/status')
  File "/home/spectre/.virtualenvs/localize/lib/python3.10/site-packages/prisma/engine/_http.py", line 217, in request
    response = await self.session.request(method, url, **kwargs)
  File "/home/spectre/.virtualenvs/localize/lib/python3.10/site-packages/prisma/_async_http.py", line 26, in request
    return Response(await self.session.request(method, url, **kwargs))
  File "/home/spectre/.virtualenvs/localize/lib/python3.10/site-packages/httpx/_client.py", line 1540, in request
    return await self.send(request, auth=auth, follow_redirects=follow_redirects)
  File "/home/spectre/.virtualenvs/localize/lib/python3.10/site-packages/httpx/_client.py", line 1629, in send
    response = await self._send_handling_auth(
  File "/home/spectre/.virtualenvs/localize/lib/python3.10/site-packages/httpx/_client.py", line 1657, in _send_handling_auth
    response = await self._send_handling_redirects(
  File "/home/spectre/.virtualenvs/localize/lib/python3.10/site-packages/httpx/_client.py", line 1694, in _send_handling_redirects
    response = await self._send_single_request(request)
  File "/home/spectre/.virtualenvs/localize/lib/python3.10/site-packages/httpx/_client.py", line 1730, in _send_single_request
    response = await transport.handle_async_request(request)
  File "/home/spectre/.virtualenvs/localize/lib/python3.10/site-packages/httpx/_transports/default.py", line 393, in handle_async_request
    with map_httpcore_exceptions():
  File "/usr/lib/python3.10/contextlib.py", line 153, in __exit__
    self.gen.throw(typ, value, traceback)
  File "/home/spectre/.virtualenvs/localize/lib/python3.10/site-packages/httpx/_transports/default.py", line 118, in map_httpcore_exceptions
    raise mapped_exc(message) from exc
httpx.ConnectError: All connection attempts failed

The above exception was the direct cause of the following exception:

Traceback (most recent call last):
  File "/home/spectre/.virtualenvs/localize/lib/python3.10/site-packages/starlette/routing.py", line 692, in lifespan
    async with self.lifespan_context(app) as maybe_state:
  File "/home/spectre/.virtualenvs/localize/lib/python3.10/site-packages/starlette/routing.py", line 569, in __aenter__
    await self._router.startup()
  File "/home/spectre/.virtualenvs/localize/lib/python3.10/site-packages/starlette/routing.py", line 669, in startup
    await handler()
  File "/run/media/spectre/Elements/Projects/GraduationProject/Complete/Attention/app.py", line 313, in startup
    await prisma.connect()
  File "/home/spectre/.virtualenvs/localize/lib/python3.10/site-packages/prisma/_base_client.py", line 442, in connect
    await self._internal_engine.connect(
  File "/home/spectre/.virtualenvs/localize/lib/python3.10/site-packages/prisma/engine/_query.py", line 350, in connect
    await self.spawn(file, timeout=timeout, datasources=datasources)
  File "/home/spectre/.virtualenvs/localize/lib/python3.10/site-packages/prisma/engine/_query.py", line 389, in spawn
    raise errors.EngineConnectionError('Could not connect to the query engine') from last_exc
prisma.engine.errors.EngineConnectionError: Could not connect to the query engine

ERROR:    Application startup failed. Exiting.
