2025-03-14 13:54:55.875400: I external/local_xla/xla/tsl/cuda/cudart_stub.cc:32] Could not find cuda drivers on your machine, GPU will not be used.
2025-03-14 13:54:55.880298: I external/local_xla/xla/tsl/cuda/cudart_stub.cc:32] Could not find cuda drivers on your machine, GPU will not be used.
2025-03-14 13:54:55.895708: E external/local_xla/xla/stream_executor/cuda/cuda_fft.cc:477] Unable to register cuFFT factory: Attempting to register factory for plugin cuFFT when one has already been registered
WARNING: All log messages before absl::InitializeLog() is called are written to STDERR
E0000 00:00:1741953295.921352  657918 cuda_dnn.cc:8310] Unable to register cuDNN factory: Attempting to register factory for plugin cuDNN when one has already been registered
E0000 00:00:1741953295.928707  657918 cuda_blas.cc:1418] Unable to register cuBLAS factory: Attempting to register factory for plugin cuBLAS when one has already been registered
2025-03-14 13:54:55.955385: I tensorflow/core/platform/cpu_feature_guard.cc:210] This TensorFlow binary is optimized to use available CPU instructions in performance-critical operations.
To enable the following instructions: AVX2 FMA, in other operations, rebuild TensorFlow with the appropriate compiler flags.
INFO:     Started server process [657918]
INFO:     Waiting for application startup.
{"is_panic":false,"message":"Can't reach database server at `localhost:5432`\n\nPlease make sure your database server is running at `localhost:5432`.","meta":{"database_host":"localhost","database_port":5432},"error_code":"P1001"}
ERROR:    Traceback (most recent call last):
  File "/home/spectre/.virtualenvs/localize/lib/python3.10/site-packages/httpx/_transports/default.py", line 101, in map_httpcore_exceptions
    yield
  File "/home/spectre/.virtualenvs/localize/lib/python3.10/site-packages/httpx/_transports/default.py", line 394, in handle_async_request
    resp = await self._pool.handle_async_request(req)
  File "/home/spectre/.virtualenvs/localize/lib/python3.10/site-packages/httpcore/_async/connection_pool.py", line 256, in handle_async_request
    raise exc from None
  File "/home/spectre/.virtualenvs/localize/lib/python3.10/site-packages/httpcore/_async/connection_pool.py", line 236, in handle_async_request
    response = await connection.handle_async_request(
  File "/home/spectre/.virtualenvs/localize/lib/python3.10/site-packages/httpcore/_async/connection.py", line 101, in handle_async_request
    raise exc
  File "/home/spectre/.virtualenvs/localize/lib/python3.10/site-packages/httpcore/_async/connection.py", line 78, in handle_async_request
    stream = await self._connect(request)
  File "/home/spectre/.virtualenvs/localize/lib/python3.10/site-packages/httpcore/_async/connection.py", line 124, in _connect
    stream = await self._network_backend.connect_tcp(**kwargs)
  File "/home/spectre/.virtualenvs/localize/lib/python3.10/site-packages/httpcore/_backends/auto.py", line 31, in connect_tcp
    return await self._backend.connect_tcp(
  File "/home/spectre/.virtualenvs/localize/lib/python3.10/site-packages/httpcore/_backends/anyio.py", line 113, in connect_tcp
    with map_exceptions(exc_map):
  File "/usr/lib/python3.10/contextlib.py", line 153, in __exit__
    self.gen.throw(typ, value, traceback)
  File "/home/spectre/.virtualenvs/localize/lib/python3.10/site-packages/httpcore/_exceptions.py", line 14, in map_exceptions
    raise to_exc(exc) from exc
httpcore.ConnectError: All connection attempts failed

The above exception was the direct cause of the following exception:

Traceback (most recent call last):
  File "/home/spectre/.virtualenvs/localize/lib/python3.10/site-packages/prisma/engine/_query.py", line 368, in spawn
    data = await self.request('GET', '/status')
  File "/home/spectre/.virtualenvs/localize/lib/python3.10/site-packages/prisma/engine/_http.py", line 217, in request
    response = await self.session.request(method, url, **kwargs)
  File "/home/spectre/.virtualenvs/localize/lib/python3.10/site-packages/prisma/_async_http.py", line 26, in request
    return Response(await self.session.request(method, url, **kwargs))
  File "/home/spectre/.virtualenvs/localize/lib/python3.10/site-packages/httpx/_client.py", line 1540, in request
    return await self.send(request, auth=auth, follow_redirects=follow_redirects)
  File "/home/spectre/.virtualenvs/localize/lib/python3.10/site-packages/httpx/_client.py", line 1629, in send
    response = await self._send_handling_auth(
  File "/home/spectre/.virtualenvs/localize/lib/python3.10/site-packages/httpx/_client.py", line 1657, in _send_handling_auth
    response = await self._send_handling_redirects(
  File "/home/spectre/.virtualenvs/localize/lib/python3.10/site-packages/httpx/_client.py", line 1694, in _send_handling_redirects
    response = await self._send_single_request(request)
  File "/home/spectre/.virtualenvs/localize/lib/python3.10/site-packages/httpx/_client.py", line 1730, in _send_single_request
    response = await transport.handle_async_request(request)
  File "/home/spectre/.virtualenvs/localize/lib/python3.10/site-packages/httpx/_transports/default.py", line 393, in handle_async_request
    with map_httpcore_exceptions():
  File "/usr/lib/python3.10/contextlib.py", line 153, in __exit__
    self.gen.throw(typ, value, traceback)
  File "/home/spectre/.virtualenvs/localize/lib/python3.10/site-packages/httpx/_transports/default.py", line 118, in map_httpcore_exceptions
    raise mapped_exc(message) from exc
httpx.ConnectError: All connection attempts failed

The above exception was the direct cause of the following exception:

Traceback (most recent call last):
  File "/home/spectre/.virtualenvs/localize/lib/python3.10/site-packages/starlette/routing.py", line 692, in lifespan
    async with self.lifespan_context(app) as maybe_state:
  File "/home/spectre/.virtualenvs/localize/lib/python3.10/site-packages/starlette/routing.py", line 569, in __aenter__
    await self._router.startup()
  File "/home/spectre/.virtualenvs/localize/lib/python3.10/site-packages/starlette/routing.py", line 669, in startup
    await handler()
  File "/run/media/spectre/Elements/Projects/GraduationProject/Complete/Recognition/app.py", line 19, in startup
    await prisma.connect()
  File "/home/spectre/.virtualenvs/localize/lib/python3.10/site-packages/prisma/_base_client.py", line 442, in connect
    await self._internal_engine.connect(
  File "/home/spectre/.virtualenvs/localize/lib/python3.10/site-packages/prisma/engine/_query.py", line 350, in connect
    await self.spawn(file, timeout=timeout, datasources=datasources)
  File "/home/spectre/.virtualenvs/localize/lib/python3.10/site-packages/prisma/engine/_query.py", line 389, in spawn
    raise errors.EngineConnectionError('Could not connect to the query engine') from last_exc
prisma.engine.errors.EngineConnectionError: Could not connect to the query engine

ERROR:    Application startup failed. Exiting.
